<?xml version="1.0" encoding="utf-8"?>
<!-- This URDF was automatically created by SolidWorks to URDF Exporter! Originally created by Stephen Brawner (brawner@gmail.com) 
     Commit Version: 1.6.0-4-g7f85cfe  Build Version: 1.6.7995.38578
     For more information, please see http://wiki.ros.org/sw_urdf_exporter -->
<robot
  name="arm2">
  <link
    name="base_link">
    <inertial>
      <origin
        xyz="3.64712918380673E-06 0.000108485822743032 0.0426868054361259"
        rpy="0 0 0" />
      <mass
        value="0.310009648045226" />
      <inertia
        ixx="0.000663841105784259"
        ixy="-2.01852564352612E-07"
        ixz="-7.24008397940951E-08"
        iyy="0.000662262169998491"
        iyz="7.62180456506448E-07"
        izz="0.00040693586759598" />
    </inertial>
    <visual>
      <origin
        xyz="0 0 0"
        rpy="0 0 0" />
      <geometry>
        <mesh
          filename="package://ti5_description/meshes/arm2/base_link.STL" />
      </geometry>
      <material
        name="">
        <color
          rgba="0.898039215686275 0.917647058823529 0.929411764705882 1" />
      </material>
    </visual>
    <collision>
      <origin
        xyz="0 0 0"
        rpy="0 0 0" />
      <geometry>
        <mesh
          filename="package://ti5_description/meshes/arm2/base_link.STL" />
      </geometry>
    </collision>
  </link>
  <link
    name="A">
    <inertial>
      <origin
        xyz="-0.0319174281182351 -1.10358807615396E-05 0.0399976516629525"
        rpy="0 0 0" />
      <mass
        value="0.262025379655418" />
      <inertia
        ixx="0.000297140969699035"
        ixy="7.84271117752949E-08"
        ixz="0.000114637900705496"
        iyy="0.000414716336390074"
        iyz="1.86561240073473E-07"
        izz="0.000394922707977513" />
    </inertial>
    <visual>
      <origin
        xyz="0 0 0"
        rpy="0 0 0" />
      <geometry>
        <mesh
          filename="package://ti5_description/meshes/arm2/A.STL" />
      </geometry>
      <material
        name="">
        <color
          rgba="0.792156862745098 0.819607843137255 0.933333333333333 1" />
      </material>
    </visual>
    <collision>
      <origin
        xyz="0 0 0"
        rpy="0 0 0" />
      <geometry>
        <mesh
          filename="package://ti5_description/meshes/arm2/A.STL" />
      </geometry>
    </collision>
  </link>
  <joint
    name="A"
    type="revolute">
    <origin
      xyz="0 0 0.1081"
      rpy="0 0 0" />
    <parent
      link="base_link" />
    <child
      link="A" />
    <axis
      xyz="0 0 1" />
    <limit
      lower="-3.14"
      upper="3.14"
      effort="0"
      velocity="0" />
  </joint>
  <link
    name="B">
    <inertial>
      <origin
        xyz="-0.0169220705616018 -3.35796567496605E-08 0.138649575742114"
        rpy="0 0 0" />
      <mass
        value="0.522901500489241" />
      <inertia
        ixx="0.00554059117370477"
        ixy="-1.52663452880238E-09"
        ixz="-0.000379561878307941"
        iyy="0.00549086309533987"
        iyz="1.09722427503113E-08"
        izz="0.000400432027570517" />
    </inertial>
    <visual>
      <origin
        xyz="0 0 0"
        rpy="0 0 0" />
      <geometry>
        <mesh
          filename="package://ti5_description/meshes/arm2/B.STL" />
      </geometry>
      <material
        name="">
        <color
          rgba="0.898039215686275 0.917647058823529 0.929411764705882 1" />
      </material>
    </visual>
    <collision>
      <origin
        xyz="0 0 0"
        rpy="0 0 0" />
      <geometry>
        <mesh
          filename="package://ti5_description/meshes/arm2/B.STL" />
      </geometry>
    </collision>
  </link>
  <joint
    name="B"
    type="revolute">
    <origin
      xyz="-0.085 0 0.0505"
      rpy="0 0 0" />
    <parent
      link="A" />
    <child
      link="B" />
    <axis
      xyz="-1 0 0" />
    <limit
      lower="-1.9"
      upper="1.9"
      effort="0"
      velocity="0" />
  </joint>
  <link
    name="C">
    <inertial>
      <origin
        xyz="0.0340031486322489 -7.2873309634458E-06 0.033729869512955"
        rpy="0 0 0" />
      <mass
        value="0.168466678560815" />
      <inertia
        ixx="0.000225542998851715"
        ixy="3.56884706826073E-08"
        ixz="-5.68792841062497E-05"
        iyy="0.000230936695379756"
        iyz="-4.3077482471074E-08"
        izz="0.000146254916028285" />
    </inertial>
    <visual>
      <origin
        xyz="0 0 0"
        rpy="0 0 0" />
      <geometry>
        <mesh
          filename="package://ti5_description/meshes/arm2/C.STL" />
      </geometry>
      <material
        name="">
        <color
          rgba="0.792156862745098 0.819607843137255 0.933333333333333 1" />
      </material>
    </visual>
    <collision>
      <origin
        xyz="0 0 0"
        rpy="0 0 0" />
      <geometry>
        <mesh
          filename="package://ti5_description/meshes/arm2/C.STL" />
      </geometry>
    </collision>
  </link>
  <joint
    name="C"
    type="revolute">
    <origin
      xyz="0.0435000000000024 0 0.26"
      rpy="0 0 0" />
    <parent
      link="B" />
    <child
      link="C" />
    <axis
      xyz="1 0 0" />
    <limit
      lower="-2.8"
      upper="2.8"
      effort="0"
      velocity="0" />
  </joint>
  <link
    name="D">
    <inertial>
      <origin
        xyz="-0.0526413484471042 3.81808755833823E-07 0.090827864242118"
        rpy="0 0 0" />
      <mass
        value="0.378966067029056" />
      <inertia
        ixx="0.00171022894051462"
        ixy="-1.1524970105476E-08"
        ixz="0.000629535570610479"
        iyy="0.00205010638516621"
        iyz="7.68932488210517E-08"
        izz="0.000643913030253886" />
    </inertial>
    <visual>
      <origin
        xyz="0 0 0"
        rpy="0 0 0" />
      <geometry>
        <mesh
          filename="package://ti5_description/meshes/arm2/D.STL" />
      </geometry>
      <material
        name="">
        <color
          rgba="0.792156862745098 0.819607843137255 0.933333333333333 1" />
      </material>
    </visual>
    <collision>
      <origin
        xyz="0 0 0"
        rpy="0 0 0" />
      <geometry>
        <mesh
          filename="package://ti5_description/meshes/arm2/D.STL" />
      </geometry>
    </collision>
  </link>
  <joint
    name="D"
    type="revolute">
    <origin
      xyz="0.041500000000002 0 0.085"
      rpy="0 0 0" />
    <parent
      link="C" />
    <child
      link="D" />
    <axis
      xyz="0 0 1" />
    <limit
      lower="-3.14"
      upper="3.14"
      effort="0"
      velocity="0" />
  </joint>
  <link
    name="E">
    <inertial>
      <origin
        xyz="0.0340031486118436 -0.0337298694164482 -7.28730645338516E-06"
        rpy="0 0 0" />
      <mass
        value="0.168466678849088" />
      <inertia
        ixx="0.000225542999087474"
        ixy="5.68792853547684E-05"
        ixz="3.56890348073381E-08"
        iyy="0.000146254916485046"
        iyz="4.3078095741883E-08"
        izz="0.000230936693051819" />
    </inertial>
    <visual>
      <origin
        xyz="0 0 0"
        rpy="0 0 0" />
      <geometry>
        <mesh
          filename="package://ti5_description/meshes/arm2/E.STL" />
      </geometry>
      <material
        name="">
        <color
          rgba="0.792156862745098 0.819607843137255 0.933333333333333 1" />
      </material>
    </visual>
    <collision>
      <origin
        xyz="0 0 0"
        rpy="0 0 0" />
      <geometry>
        <mesh
          filename="package://ti5_description/meshes/arm2/E.STL" />
      </geometry>
    </collision>
  </link>
  <joint
    name="E"
    type="revolute">
    <origin
      xyz="-0.0415 0 0.1745"
      rpy="-1.5708 0 0" />
    <parent
      link="D" />
    <child
      link="E" />
    <axis
      xyz="1 0 0" />
    <limit
      lower="-3.14"
      upper="3.14"
      effort="0"
      velocity="0" />
  </joint>
  <link
    name="F">
    <inertial>
      <origin
        xyz="6.93889390390723E-18 -0.00750000000000005 1.11022302462516E-16"
        rpy="0 0 0" />
      <mass
        value="0.0282743338823081" />
      <inertia
        ixx="6.59734457253857E-06"
        ixy="-4.09859912135662E-22"
        ixz="-6.22039820639877E-22"
        iyy="1.27234502470387E-05"
        iyz="1.85353372867789E-22"
        izz="6.59734457253857E-06" />
    </inertial>
    <visual>
      <origin
        xyz="0 0 0"
        rpy="0 0 0" />
      <geometry>
        <mesh
          filename="package://ti5_description/meshes/arm2/F.STL" />
      </geometry>
      <material
        name="">
        <color
          rgba="1 1 1 1" />
      </material>
    </visual>
    <collision>
      <origin
        xyz="0 0 0"
        rpy="0 0 0" />
      <geometry>
        <mesh
          filename="package://ti5_description/meshes/arm2/F.STL" />
      </geometry>
    </collision>
  </link>
  <joint
    name="F"
    type="revolute">
    <origin
      xyz="0.0415 -0.085 0"
      rpy="0 0 0" />
    <parent
      link="E" />
    <child
      link="F" />
    <axis
      xyz="0 -1 0" />
    <limit
      lower="-3.14"
      upper="3.14"
      effort="0"
      velocity="0" />
  </joint>
  <!--left hand assemble-->
      <link name="L_hand_base_link">
      <inertial>
        <origin
          xyz="-0.002551 -0.066047 -0.0019357"
          rpy="0 0 0" />
        <mass
          value="0.14143" />
        <inertia
          ixx="0.0001234"
          ixy="2.1995E-06"
          ixz="-1.7694E-06"
          iyy="8.3835E-05"
          iyz="1.5968E-06"
          izz="7.7231E-05" />
      </inertial>
      <visual>
        <origin
          xyz="0 0 0"
          rpy="0 0 0" />
        <geometry>
          <mesh filename="./meshes/L_hand_base_link.STL" />
        </geometry>
        <material name="">
          <color rgba="0.1 0.1 0.1 1" />
        </material>
      </visual>
      <collision>
        <origin
          xyz="0 0 0"
          rpy="0 0 0" />
        <geometry>
          <mesh filename="./meshes/L_hand_base_link.STL" />
        </geometry>
      </collision>
    </link>
    <!-- fixed link--> 
    <joint
      name="fixed_joint"
      type="fixed">
      <origin
        xyz="-0 0 0"
        rpy="0 90 0" />
      <parent
        link="F" />
      <child
        link="L_hand_base_link" />
    </joint>
 
    <link name="L_thumb_proximal_base">
      <inertial>
        <origin
          xyz="0.0048817 0.00038782 -0.00722"
          rpy="0 0 0" />
        <mass
          value="0.0018869" />
        <inertia
          ixx="5.5158E-08"
          ixy="-1.1803E-08"
          ixz="-4.6743E-09"
          iyy="8.2164E-08"
          iyz="-1.3521E-09"
          izz="6.7434E-08" />
      </inertial>
      <visual>
        <origin
          xyz="0 0 0"
          rpy="0 0 0" />
        <geometry>
          <mesh filename="./meshes/Link11_L.STL" />
        </geometry>
        <material name="">
          <color rgba="0.1 0.1 0.1 1" />
        </material>
      </visual>
      <collision>
        <origin
          xyz="0 0 0"
          rpy="0 0 0" />
        <geometry>
          <mesh filename="./meshes/Link11_L.STL" />
        </geometry>
      </collision>
    </link>

    <joint
      name="L_thumb_proximal_yaw_joint"
      type="revolute">
      <origin
        xyz="-0.01696 -0.0691 0.02045"
        rpy="1.5708 -1.5708 0" />
      <parent
        link="L_hand_base_link" />
      <child
        link="L_thumb_proximal_base" />
      <axis
        xyz="0 0 1" />
      <limit
        lower="-0.1"
        upper="1.3"
        effort="1"
        velocity="0.5" />
    </joint>

    <link name="L_thumb_proximal">
      <inertial>
        <origin
          xyz="0.021936 -0.01279 -0.0080386"
          rpy="0 0 0" />
        <mass
          value="0.0066101" />
        <inertia
          ixx="1.5693E-06"
          ixy="7.8339E-07"
          ixz="8.5959E-10"
          iyy="1.7356E-06"
          iyz="1.0378E-09"
          izz="2.787E-06" />
      </inertial>
      <visual>
        <origin
          xyz="0 0 0"
          rpy="0 0 0" />
        <geometry>
          <mesh filename="./meshes/Link12_L.STL" />
        </geometry>
        <material name="">
          <color rgba="0.1 0.1 0.1 1" />
        </material>
      </visual>
      <collision>
        <origin
          xyz="0 0 0"
          rpy="0 0 0" />
        <geometry>
          <mesh filename="./meshes/Link12_L.STL" />
        </geometry>
      </collision>
    </link>

    <joint
      name="L_thumb_proximal_pitch_joint"
      type="revolute">
      <origin
        xyz="0.0099867 0.0098242 -0.0089"
        rpy="-1.5708 0 0.16939" />
      <parent
        link="L_thumb_proximal_base" />
      <child
        link="L_thumb_proximal" />
      <axis
        xyz="0 0 -1" />
      <limit
        lower="0.0"
        upper="0.5"
        effort="1"
        velocity="0.5" />
    </joint>

    <link name="L_thumb_intermediate">
      <inertial>
        <origin
          xyz="0.0095531 0.0016282 -0.0072002"
          rpy="0 0 0" />
        <mass
          value="0.0037844" />
        <inertia
          ixx="3.6981E-07"
          ixy="9.8603E-08"
          ixz="-2.8173E-12"
          iyy="3.2395E-07"
          iyz="-2.8028E-12"
          izz="4.6532E-07" />
      </inertial>
      <visual>
        <origin
          xyz="0 0 0"
          rpy="0 0 0" />
        <geometry>
          <mesh filename="./meshes/Link13_L.STL" />
        </geometry>
        <material name="">
          <color rgba="0.1 0.1 0.1 1" />
        </material>
      </visual>
      <collision>
        <origin
          xyz="0 0 0"
          rpy="0 0 0" />
        <geometry>
          <mesh filename="./meshes/Link13_L.STL" />
        </geometry>
      </collision>
    </link>

    <joint
      name="L_thumb_intermediate_joint"
      type="revolute">
      <origin
        xyz="0.04407 -0.034553 -0.0008"
        rpy="0 0 0" />
      <parent
        link="L_thumb_proximal" />
      <child
        link="L_thumb_intermediate" />
      <axis
        xyz="0 0 -1" />
      <limit
        lower="0"
        upper="0.8"
        effort="1"
        velocity="0.5" />
      <mimic 
        joint="L_thumb_proximal_pitch_joint"
        multiplier="1.6"
        offset="0" />
    </joint>

    <link name="L_thumb_distal">
      <inertial>
        <origin
          xyz="0.0092888 -0.004953 -0.0060033"
          rpy="0 0 0" />
        <mass
          value="0.003344" />
        <inertia
          ixx="1.3632E-07"
          ixy="5.6787E-08"
          ixz="-9.1939E-11"
          iyy="1.4052E-07"
          iyz="1.2145E-10"
          izz="2.0026E-07" />
      </inertial>
      <visual>
        <origin
          xyz="0 0 0"
          rpy="0 0 0" />
        <geometry>
          <mesh filename="./meshes/Link14_L.STL" />
        </geometry>
        <material name="">
          <color rgba="0.1 0.1 0.1 1" />
        </material>
      </visual>
      <collision>
        <origin
          xyz="0 0 0"
          rpy="0 0 0" />
        <geometry>
          <mesh filename="./meshes/Link14_L.STL" />
        </geometry>
      </collision>
    </link>

    <joint
      name="L_thumb_distal_joint"
      type="revolute">
      <origin
        xyz="0.020248 -0.010156 -0.0012"
        rpy="0 0 0" />
      <parent
        link="L_thumb_intermediate" />
      <child
        link="L_thumb_distal" />
      <axis
        xyz="0 0 -1" />
      <limit
        lower="0"
        upper="1.2"
        effort="1"
        velocity="0.5" />
      <mimic 
        joint="L_thumb_proximal_pitch_joint"
        multiplier="2.4"
        offset="0" />
    </joint>

    <link name="L_index_proximal">
      <inertial>
        <origin
          xyz="0.0012971 -0.011934 -0.0059998"
          rpy="0 0 0" />
        <mass
          value="0.0042405" />
        <inertia
          ixx="6.6215E-07"
          ixy="1.8442E-08"
          ixz="1.3746E-12"
          iyy="2.1167E-07"
          iyz="-1.4773E-11"
          izz="6.9402E-07" />
      </inertial>
      <visual>
        <origin
          xyz="0 0 0"
          rpy="0 0 0" />
        <geometry>
          <mesh filename="./meshes/Link15_L.STL" />
        </geometry>
        <material name="">
          <color rgba="0.1 0.1 0.1 1" />
        </material>
      </visual>
      <collision>
        <origin
          xyz="0 0 0"
          rpy="0 0 0" />
        <geometry>
          <mesh filename="./meshes/Link15_L.STL" />
        </geometry>
      </collision>
    </link>

    <link name="L_thumb_tip">
    <visual>
      <origin
        xyz="0 0 0"
        rpy="0 0 0" />
      <geometry>
        <sphere radius="0.005"/>
      </geometry>
      <material name="green">
        <color rgba="0 1 0 1" />
      </material>
    </visual>
  </link>
  <joint name="L_thumb_tip_joint" type="fixed">
    <parent link="L_thumb_distal"/>
    <child link="L_thumb_tip"/>
    <origin rpy="0 0 0" xyz="0.015 -0.013 -0.004"/>
  </joint>

    <joint
      name="L_index_proximal_joint"
      type="revolute">
      <origin
        xyz="0.00028533 -0.13653 0.032268"
        rpy="-0.034907 0 0" />
      <parent
        link="L_hand_base_link" />
      <child
        link="L_index_proximal" />
      <axis
        xyz="0 0 -1" />
      <limit
        lower="0"
        upper="1.7"
        effort="1"
        velocity="0.5" />
    </joint>

    <link name="L_index_intermediate">
      <inertial>
        <origin
          xyz="0.0021753 -0.019567 -0.005"
          rpy="0 0 0" />
        <mass
          value="0.0045682" />
        <inertia
          ixx="7.6284E-07"
          ixy="-8.063E-08"
          ixz="3.6797E-13"
          iyy="9.4308E-08"
          iyz="1.5743E-13"
          izz="7.8176E-07" />
      </inertial>
      <visual>
        <origin
          xyz="0 0 0"
          rpy="0 0 0" />
        <geometry>
          <mesh filename="./meshes/Link16_L.STL" />
        </geometry>
        <material name="">
          <color rgba="0.1 0.1 0.1 1" />
        </material>
      </visual>
      <collision>
        <origin
          xyz="0 0 0"
          rpy="0 0 0" />
        <geometry>
          <mesh filename="./meshes/Link16_L.STL" />
        </geometry>
      </collision>
    </link>

    <joint
      name="L_index_intermediate_joint"
      type="revolute">
      <origin
        xyz="-0.0024229 -0.032041 -0.001"
        rpy="0 0 0" />
      <parent
        link="L_index_proximal" />
      <child
        link="L_index_intermediate" />
      <axis
        xyz="0 0 -1" />
      <limit
        lower="0"
        upper="1.7"
        effort="1"
        velocity="0.5" />
      <mimic 
        joint="L_index_proximal_joint"
        multiplier="1"
        offset="0" />
    </joint>

    <link name="L_index_tip">
    <visual>
      <origin
        xyz="0 0 0"
        rpy="0 0 0" />
      <geometry>
        <sphere radius="0.005"/>
      </geometry>
      <material name="green">
        <color rgba="0 1 0 1" />
      </material>
    </visual>
  </link>
  <joint name="L_index_tip_joint" type="fixed">
    <parent link="L_index_intermediate"/>
    <child link="L_index_tip"/>
    <origin rpy="0 0 0" xyz="-0.005 -0.04 -0.004"/>
  </joint>

    <link name="L_middle_proximal">
      <inertial>
        <origin
          xyz="0.0012971 -0.011934 -0.0059999"
          rpy="0 0 0" />
        <mass
          value="0.0042405" />
        <inertia
          ixx="6.6215E-07"
          ixy="1.8442E-08"
          ixz="1.2299E-12"
          iyy="2.1167E-07"
          iyz="-1.4484E-11"
          izz="6.9402E-07" />
      </inertial>
      <visual>
        <origin
          xyz="0 0 0"
          rpy="0 0 0" />
        <geometry>
          <mesh filename="./meshes/Link17_L.STL" />
        </geometry>
        <material name="">
          <color rgba="0.1 0.1 0.1 1" />
        </material>
      </visual>
      <collision>
        <origin
          xyz="0 0 0"
          rpy="0 0 0" />
        <geometry>
          <mesh filename="./meshes/Link17_L.STL" />
        </geometry>
      </collision>
    </link>

    <joint
      name="L_middle_proximal_joint"
      type="revolute">
      <origin
        xyz="0.00028533 -0.1371 0.01295"
        rpy="0 0 0" />
      <parent
        link="L_hand_base_link" />
      <child
        link="L_middle_proximal" />
      <axis
        xyz="0 0 -1" />
      <limit
        lower="0"
        upper="1.7"
        effort="1"
        velocity="0.5" />
    </joint>

    <link name="L_middle_intermediate">
      <inertial>
        <origin
          xyz="0.001921 -0.020796 -0.0049999"
          rpy="0 0 0" />
        <mass
          value="0.0050397" />
        <inertia
          ixx="9.5823E-07"
          ixy="-1.1425E-07"
          ixz="-2.4186E-12"
          iyy="1.0646E-07"
          iyz="3.6974E-12"
          izz="9.8385E-07" />
      </inertial>
      <visual>
        <origin
          xyz="0 0 0"
          rpy="0 0 0" />
        <geometry>
          <mesh filename="./meshes/Link18_L.STL" />
        </geometry>
        <material name="">
          <color rgba="0.1 0.1 0.1 1" />
        </material>
      </visual>
      <collision>
        <origin
          xyz="0 0 0"
          rpy="0 0 0" />
        <geometry>
          <mesh filename="./meshes/Link18_L.STL" />
        </geometry>
      </collision>
    </link>
    
    <joint
      name="L_middle_intermediate_joint"
      type="revolute">
      <origin
        xyz="-0.0024229 -0.032041 -0.001"
        rpy="0 0 0" />
      <parent
        link="L_middle_proximal" />
      <child
        link="L_middle_intermediate" />
      <axis
        xyz="0 0 -1" />
      <limit
        lower="0"
        upper="1.7"
        effort="1"
        velocity="0.5" />
      <mimic 
        joint="L_middle_proximal_joint"
        multiplier="1"
        offset="0" />
    </joint>

    <link name="L_middle_tip">
    <visual>
      <origin
        xyz="0 0 0"
        rpy="0 0 0" />
      <geometry>
        <sphere radius="0.005"/>
      </geometry>
      <material name="green">
        <color rgba="0 1 0 1" />
      </material>
    </visual>
  </link>
  <joint name="L_middle_tip_joint" type="fixed">
    <parent link="L_middle_intermediate"/>
    <child link="L_middle_tip"/>
    <origin rpy="0 0 0" xyz="-0.005 -0.045 -0.004"/>
  </joint>

    <link name="L_ring_proximal">
      <inertial>
        <origin
          xyz="0.0012971 -0.011934 -0.0059999"
          rpy="0 0 0" />
        <mass
          value="0.0042405" />
        <inertia
          ixx="6.6215E-07"
          ixy="1.8442E-08"
          ixz="9.6052E-13"
          iyy="2.1167E-07"
          iyz="-1.4124E-11"
          izz="6.9402E-07" />
      </inertial>
      <visual>
        <origin
          xyz="0 0 0"
          rpy="0 0 0" />
        <geometry>
          <mesh filename="./meshes/Link19_L.STL" />
        </geometry>
        <material name="">
          <color rgba="0.1 0.1 0.1 1" />
        </material>
      </visual>
      <collision>
        <origin
          xyz="0 0 0"
          rpy="0 0 0" />
        <geometry>
          <mesh filename="./meshes/Link19_L.STL" />
        </geometry>
      </collision>
    </link>

    <joint
      name="L_ring_proximal_joint"
      type="revolute">
      <origin
        xyz="0.00028533 -0.13691 -0.0062872"
        rpy="0.05236 0 0" />
      <parent
        link="L_hand_base_link" />
      <child
        link="L_ring_proximal" />
      <axis
        xyz="0 0 -1" />
      <limit
        lower="0"
        upper="1.7"
        effort="1"
        velocity="0.5" />
    </joint>

    <link name="L_ring_intermediate">
      <inertial>
        <origin
          xyz="0.0021753 -0.019567 -0.005"
          rpy="0 0 0" />
        <mass
          value="0.0045682" />
        <inertia
          ixx="7.6285E-07"
          ixy="-8.0631E-08"
          ixz="3.3472E-14"
          iyy="9.4308E-08"
          iyz="-4.4773E-13"
          izz="7.8176E-07" />
      </inertial>
      <visual>
        <origin
          xyz="0 0 0"
          rpy="0 0 0" />
        <geometry>
          <mesh filename="./meshes/Link20_L.STL" />
        </geometry>
        <material name="">
          <color rgba="0.1 0.1 0.1 1" />
        </material>
      </visual>
      <collision>
        <origin
          xyz="0 0 0"
          rpy="0 0 0" />
        <geometry>
          <mesh filename="./meshes/Link20_L.STL" />
        </geometry>
      </collision>
    </link>

    <joint
      name="L_ring_intermediate_joint"
      type="revolute">
      <origin
        xyz="-0.0024229 -0.032041 -0.001"
        rpy="0 0 0" />
      <parent
        link="L_ring_proximal" />
      <child
        link="L_ring_intermediate" />
      <axis
        xyz="0 0 -1" />
      <limit
        lower="0"
        upper="1.7"
        effort="1"
        velocity="0.5" />
      <mimic 
        joint="L_ring_proximal_joint"
        multiplier="1"
        offset="0" />
    </joint>

    <link name="L_ring_tip">
    <visual>
      <origin
        xyz="0 0 0"
        rpy="0 0 0" />
      <geometry>
        <sphere radius="0.005"/>
      </geometry>
      <material name="green">
        <color rgba="0 1 0 1" />
      </material>
    </visual>
  </link>
  <joint name="L_ring_tip_joint" type="fixed">
    <parent link="L_ring_intermediate"/>
    <child link="L_ring_tip"/>
    <origin rpy="0 0 0" xyz="-0.002 -0.04 -0.004"/>
  </joint>

    <link name="L_pinky_proximal">
      <inertial>
        <origin
          xyz="0.0012971 -0.011934 -0.0059999"
          rpy="0 0 0" />
        <mass
          value="0.0042405" />
        <inertia
          ixx="6.6215E-07"
          ixy="1.8442E-08"
          ixz="1.0279E-12"
          iyy="2.1167E-07"
          iyz="-1.4277E-11"
          izz="6.9402E-07" />
      </inertial>
      <visual>
        <origin
          xyz="0 0 0"
          rpy="0 0 0" />
        <geometry>
          <mesh filename="./meshes/Link21_L.STL" />
        </geometry>
        <material name="">
          <color rgba="0.1 0.1 0.1 1" />
        </material>
      </visual>
      <collision>
        <origin
          xyz="0 0 0"
          rpy="0 0 0" />
        <geometry>
          <mesh filename="./meshes/Link21_L.STL" />
        </geometry>
      </collision>
    </link>

    <joint
      name="L_pinky_proximal_joint"
      type="revolute">
      <origin
        xyz="0.00028533 -0.13571 -0.025488"
        rpy="0.10472 0 0" />
      <parent
        link="L_hand_base_link" />
      <child
        link="L_pinky_proximal" />
      <axis
        xyz="0 0 -1" />
      <limit
        lower="0"
        upper="1.7"
        effort="1"
        velocity="0.5" />
    </joint>

    <link name="L_pinky_intermediate">
      <inertial>
        <origin
          xyz="0.0024788 -0.016208 -0.0050001"
          rpy="0 0 0" />
        <mass
          value="0.0036036" />
        <inertia
          ixx="4.3923E-07"
          ixy="-4.1355E-08"
          ixz="1.2263E-12"
          iyy="7.0315E-08"
          iyz="3.1311E-12"
          izz="4.4881E-07" />
      </inertial>
      <visual>
        <origin
          xyz="0 0 0"
          rpy="0 0 0" />
        <geometry>
          <mesh filename="./meshes/Link22_L.STL" />
        </geometry>
        <material name="">
          <color rgba="0.1 0.1 0.1 1" />
        </material>
      </visual>
      <collision>
        <origin
          xyz="0 0 0"
          rpy="0 0 0" />
        <geometry>
          <mesh filename="./meshes/Link22_L.STL" />
        </geometry>
      </collision>
    </link>

    <joint
      name="L_pinky_intermediate_joint"
      type="revolute">
      <origin
        xyz="-0.0024229 -0.032041 -0.001"
        rpy="0 0 0" />
      <parent
        link="L_pinky_proximal" />
      <child
        link="L_pinky_intermediate" />
      <axis
        xyz="0 0 -1" />
      <limit
        lower="0"
        upper="1.7"
        effort="1"
        velocity="0.5" />
      <mimic 
        joint="L_pinky_proximal_joint"
        multiplier="1"
        offset="0" />
    </joint>

    <link name="L_pinky_tip">
    <visual>
      <origin
        xyz="0 0 0"
        rpy="0 0 0" />
      <geometry>
        <sphere radius="0.005"/>
      </geometry>
      <material name="green">
        <color rgba="0 1 0 1" />
      </material>
    </visual>
  </link>
  <joint name="L_pinky_tip_joint" type="fixed">
    <parent link="L_pinky_intermediate"/>
    <child link="L_pinky_tip"/>
    <origin rpy="0 0 0" xyz="-0.002 -0.032 -0.004"/>
  </joint>
</robot>
